Workbook

Sheet Start Here
B2: Genesis Lumia ERP
B3: School Requirements Workbook
B4: Please fill this in and send it back — it is everything we need to set up the ERP for your school.
B6: SCHOOL | E6: PLEASE RETURN THE COMPLETED FILE TO
B7: =IF('1. School Profile'!C6="","(fills in automatically from Sheet 1)",'1. School Profile'!C6) -> (fills in automatically from Sheet 1) | E7: Jayanth · jayanth.m@ncetmail.com
B9: HOW TO FILL THIS IN
B10: 1 | C10: Work through the numbered sheets (tabs along the bottom). Each one takes 5–15 minutes.
B11: 2 | C11: Type only in the light-blue cells. Where a cell has a ▾ arrow, pick from the list.
B12: 3 | C12: The gold row on each sheet is an example of the format — overwrite it or leave it.
B13: 4 | C13: Fields marked * are required. If something does not apply to you, write 'NA'.
B14: 5 | C14: Unsure about anything? Note it in Sheet 16 — we will discuss it with you.
B15: 6 | C15: Save the file and send it back. Sending it in parts is fine — the tracker below shows what's left.
B17: COLOUR KEY
C18: Light blue — please fill in
B19: e.g. | C19: Gold — an example of the expected format
C20: White — questions and guidance from us (no need to change)
B22: YOUR PROGRESS
B23: # | C23: Section | D23: What we need | E23: Filled so far | F23: Status | G23: Go
B24: 1 | C24: School Profile | D24: Name, board, contacts, academic year, size | E24: =(COUNTA('1. School Profile'!C6:C14)+COUNTA('1. School Profile'!C17:C27)+COUNTA('1. School Profile'!C30:C35)+COUNTA('1. School Profile'!C38:C42)+COUNTA('1. School Profile'!C45:C47))&" of 34 answers" -> 0 of 34 answers | F24: =IF(AND((COUNTA('1. School Profile'!C6:C14)+COUNTA('1. School Profile'!C17:C27)+COUNTA('1. School Profile'!C30:C35)+COUNTA('1. School Profile'!C38:C42)+COUNTA('1. School Profile'!C45:C47))>=34),"Complete",IF(OR((COUNTA('1. School Profile'!C6:C14)+COUNTA('1. School Profile'!C17:C27)+COUNTA('1. School Profile'!C30:C35)+COUNTA('1. School Profile'!C38:C42)+COUNTA('1. School Profile'!C45:C47))>0),"In progress","Not started")) -> Not started | G24: =HYPERLINK("#'1. School Profile'!A1","Open →") -> Open →
B25: 2 | C25: Modules | D25: Which ERP modules you want and their priority | E25: =COUNTA('2. Modules'!D8:D21)&" of 14 decided" -> 0 of 14 decided | F25: =IF(AND(COUNTA('2. Modules'!D8:D21)>=14),"Complete",IF(OR(COUNTA('2. Modules'!D8:D21)>0),"In progress","Not started")) -> Not started | G25: =HYPERLINK("#'2. Modules'!A1","Open →") -> Open →
B26: 3 | C26: Classes | D26: Every class and section, with class teacher | E26: =COUNTA('3. Classes'!A8:A47)&IF(COUNTA('3. Classes'!A8:A47)=1," row"," rows") -> 0 rows | F26: =IF(AND(COUNTA('3. Classes'!A8:A47)>0),"Complete",IF(OR(COUNTA('3. Classes'!A8:A47)>0),"In progress","Not started")) -> Not started | G26: =HYPERLINK("#'3. Classes'!A1","Open →") -> Open →
B27: 4 | C27: Subjects | D27: Subjects, classes taught in, periods per week | E27: =COUNTA('4. Subjects'!A8:A42)&IF(COUNTA('4. Subjects'!A8:A42)=1," row"," rows") -> 0 rows | F27: =IF(AND(COUNTA('4. Subjects'!A8:A42)>0),"Complete",IF(OR(COUNTA('4. Subjects'!A8:A42)>0),"In progress","Not started")) -> Not started | G27: =HYPERLINK("#'4. Subjects'!A1","Open →") -> Open →
B28: 5 | C28: Staff | D28: Everyone who needs a login, and their role | E28: =COUNTA('5. Staff'!A9:A68)&IF(COUNTA('5. Staff'!A9:A68)=1," row"," rows") -> 0 rows | F28: =IF(AND(COUNTA('5. Staff'!A9:A68)>0),"Complete",IF(OR(COUNTA('5. Staff'!A9:A68)>0),"In progress","Not started")) -> Not started | G28: =HYPERLINK("#'5. Staff'!A1","Open →") -> Open →
B29: 6 | C29: Timetable | D29: Bell schedule and timetable rules | E29: =(COUNTA('6. Timetable'!C6:C10))&" of 5 answers"&" · "&COUNTA('6. Timetable'!A16:A30)&IF(COUNTA('6. Timetable'!A16:A30)=1," row"," rows") -> 0 of 5 answers · 0 rows | F29: =IF(AND((COUNTA('6. Timetable'!C6:C10))>=5,COUNTA('6. Timetable'!A16:A30)>0),"Complete",IF(OR((COUNTA('6. Timetable'!C6:C10))>0,COUNTA('6. Timetable'!A16:A30)>0),"In progress","Not started")) -> Not started | G29: =HYPERLINK("#'6. Timetable'!A1","Open →") -> Open →
B30: 7 | C30: Fees | D30: Fee heads, amounts, terms and due dates | E30: =(COUNTA('7. Fees'!C6:C10))&" of 5 answers"&" · "&COUNTA('7. Fees'!A16:A45)&IF(COUNTA('7. Fees'!A16:A45)=1," row"," rows") -> 0 of 5 answers · 0 rows | F30: =IF(AND((COUNTA('7. Fees'!C6:C10))>=5,COUNTA('7. Fees'!A16:A45)>0),"Complete",IF(OR((COUNTA('7. Fees'!C6:C10))>0,COUNTA('7. Fees'!A16:A45)>0),"In progress","Not started")) -> Not started | G30: =HYPERLINK("#'7. Fees'!A1","Open →") -> Open →
B31: 8 | C31: Admissions | D31: Admission process and required documents | E31: =(COUNTA('8. Admissions'!C6:C14))&" of 9 answers"&" · "&COUNTA('8. Admissions'!A19:A33)&IF(COUNTA('8. Admissions'!A19:A33)=1," row"," rows") -> 0 of 9 answers · 0 rows | F31: =IF(AND((COUNTA('8. Admissions'!C6:C14))>=9,COUNTA('8. Admissions'!A19:A33)>0),"Complete",IF(OR((COUNTA('8. Admissions'!C6:C14))>0,COUNTA('8. Admissions'!A19:A33)>0),"In progress","Not started")) -> Not started | G31: =HYPERLINK("#'8. Admissions'!A1","Open →") -> Open →
B32: 9 | C32: Hostel | D32: Hostels, rooms, visitor & gate-pass rules | E32: =(COUNTA('9. Hostel'!C6:C8))&" of 3 answers"&" · "&COUNTA('9. Hostel'!A13:A22)&IF(COUNTA('9. Hostel'!A13:A22)=1," row"," rows") -> 0 of 3 answers · 0 rows | F32: =IF(AND((COUNTA('9. Hostel'!C6:C8))>=3,COUNTA('9. Hostel'!A13:A22)>0),"Complete",IF(OR((COUNTA('9. Hostel'!C6:C8))>0,COUNTA('9. Hostel'!A13:A22)>0),"In progress","Not started")) -> Not started | G32: =HYPERLINK("#'9. Hostel'!A1","Open →") -> Open →
B33: 10 | C33: Attendance & Leave | D33: Attendance method, leave types and quotas | E33: =(COUNTA('10. Attendance & Leave'!C6:C10))&" of 5 answers"&" · "&COUNTA('10. Attendance & Leave'!A15:A26)&IF(COUNTA('10. Attendance & Leave'!A15:A26)=1," row"," rows") -> 0 of 5 answers · 0 rows | F33: =IF(AND((COUNTA('10. Attendance & Leave'!C6:C10))>=5,COUNTA('10. Attendance & Leave'!A15:A26)>0),"Complete",IF(OR((COUNTA('10. Attendance & Leave'!C6:C10))>0,COUNTA('10. Attendance & Leave'!A15:A26)>0),"In progress","Not started")) -> Not started | G33: =HYPERLINK("#'10. Attendance & Leave'!A1","Open →") -> Open →
B34: 11 | C34: Exams | D34: Exams in the year and their weightage | E34: =(COUNTA('11. Exams'!C6:C8))&" of 3 answers"&" · "&COUNTA('11. Exams'!A13:A24)&IF(COUNTA('11. Exams'!A13:A24)=1," row"," rows") -> 0 of 3 answers · 0 rows | F34: =IF(AND((COUNTA('11. Exams'!C6:C8))>=3,COUNTA('11. Exams'!A13:A24)>0),"Complete",IF(OR((COUNTA('11. Exams'!C6:C8))>0,COUNTA('11. Exams'!A13:A24)>0),"In progress","Not started")) -> Not started | G34: =HYPERLINK("#'11. Exams'!A1","Open →") -> Open →
B35: 12 | C35: Grading | D35: Grade bands (if you use grades) | E35: =COUNTA('12. Grading'!A9:A20)&IF(COUNTA('12. Grading'!A9:A20)=1," row"," rows") -> 0 rows | F35: =IF(AND(COUNTA('12. Grading'!A9:A20)>0),"Complete",IF(OR(COUNTA('12. Grading'!A9:A20)>0),"In progress","Not started")) -> Not started | G35: =HYPERLINK("#'12. Grading'!A1","Open →") -> Open →
B36: 13 | C36: Notifications | D36: Automatic SMS / email / WhatsApp messages | E36: =(COUNTA('13. Notifications'!C6:C9))&" of 4 answers"&" · "&COUNTA('13. Notifications'!C14:C24)&" of 11 decided" -> 0 of 4 answers · 0 of 11 decided | F36: =IF(AND((COUNTA('13. Notifications'!C6:C9))>=4,COUNTA('13. Notifications'!C14:C24)>=11),"Complete",IF(OR((COUNTA('13. Notifications'!C6:C9))>0,COUNTA('13. Notifications'!C14:C24)>0),"In progress","Not started")) -> Not started | G36: =HYPERLINK("#'13. Notifications'!A1","Open →") -> Open →
B37: 14 | C37: Existing Data | D37: Records we can import for you | E37: =COUNTA('14. Existing Data'!C8:C17)&" of 10 decided" -> 0 of 10 decided | F37: =IF(AND(COUNTA('14. Existing Data'!C8:C17)>=10),"Complete",IF(OR(COUNTA('14. Existing Data'!C8:C17)>0),"In progress","Not started")) -> Not started | G37: =HYPERLINK("#'14. Existing Data'!A1","Open →") -> Open →
B38: 15 | C38: Reports | D38: Reports and certificates you use today | E38: =COUNTA('15. Reports'!A8:A27)&IF(COUNTA('15. Reports'!A8:A27)=1," row"," rows") -> 0 rows | F38: =IF(AND(COUNTA('15. Reports'!A8:A27)>0),"Complete",IF(OR(COUNTA('15. Reports'!A8:A27)>0),"In progress","Not started")) -> Not started | G38: =HYPERLINK("#'15. Reports'!A1","Open →") -> Open →
B39: 16 | C39: Questions & Sign-off | D39: Open questions and who filled this in | E39: =(COUNTA('16. Questions & Sign-off'!C25:C28))&" of 4 answers"&" · "&COUNTA('16. Questions & Sign-off'!B8:B22)&IF(COUNTA('16. Questions & Sign-off'!B8:B22)=1," row"," rows") -> 0 of 4 answers · 0 rows | F39: =IF(AND((COUNTA('16. Questions & Sign-off'!C25:C28))>=4,COUNTA('16. Questions & Sign-off'!B8:B22)>0),"Complete",IF(OR((COUNTA('16. Questions & Sign-off'!C25:C28))>0,COUNTA('16. Questions & Sign-off'!B8:B22)>0),"In progress","Not started")) -> Not started | G39: =HYPERLINK("#'16. Questions & Sign-off'!A1","Open →") -> Open →
B41: Sections complete | F41: =COUNTIF(F24:F39,"Complete")&" of 16" -> 0 of 16
B43: Your answers are used only to configure your school's ERP. Questions? Contact Jayanth at jayanth.m@ncetmail.com.

Sheet 1. School Profile
A1: 1 · School Profile
A2: Who you are, how to reach you, and how your academic year runs. This sets up your school in the ERP.
A3: =HYPERLINK("#'Start Here'!A1","← Back to Start Here") -> ← Back to Start Here | C3: Light-blue cells: please fill in · Gold row: example of the format · * required
A5: SCHOOL IDENTITY
A6: 1 | B6: School name * | E6: Full name as it should appear on receipts and report cards
A7: 2 | B7: Campus / branch name | E7: e.g. Main Campus. Leave blank if you have only one campus
A8: 3 | B8: Board * | E8: Pick one; choose Other and explain in Questions sheet if needed
A9: 4 | B9: Affiliation number | E9: e.g. 1930001
A10: 5 | B10: UDISE code | E10: 11-digit code, e.g. 29200800101
A11: 6 | B11: School type * | E11: Day, residential or both
A12: 7 | B12: Students admitted * | E12: Boys, girls or co-ed
A13: 8 | B13: Year established | E13: e.g. 1962
A14: 9 | B14: Website | E14: e.g. www.sainikschool.edu.in
A16: CONTACT
A17: 1 | B17: Full address * | E17: Street, area
A18: 2 | B18: City *
A19: 3 | B19: State *
A20: 4 | B20: PIN code * | E20: 6 digits, e.g. 560001
A21: 5 | B21: Office phone * | E21: With STD code, e.g. 080-2345 6789
A22: 6 | B22: Official email * | E22: e.g. office@school.edu.in
A23: 7 | B23: Principal's name * | E23: e.g. Dr. A. Sharma
A24: 8 | B24: Principal's email *
A25: 9 | B25: Principal's mobile | E25: 10 digits
A26: 10 | B26: ERP coordinator (our main contact) * | E26: Person who will answer our questions during setup
A27: 11 | B27: Coordinator mobile & email * | E27: e.g. 98450 12345 · it.coordinator@school.edu.in
A29: ACADEMIC YEAR
A30: 1 | B30: Academic year * | E30: e.g. 2026-27
A31: 2 | B31: Session start date * | E31: e.g. 01-Apr-2026
A32: 3 | B32: Session end date * | E32: e.g. 31-Mar-2027
A33: 4 | B33: Working days * | E33: Which days classes run
A34: 5 | B34: School start time * | E34: e.g. 08:00
A35: 6 | B35: School end time * | E35: e.g. 14:30
A37: SIZE (APPROXIMATE IS FINE)
A38: 1 | B38: Total students * | E38: e.g. 850
A39: 2 | B39: Teaching staff * | E39: e.g. 48
A40: 3 | B40: Non-teaching staff | E40: e.g. 30
A41: 4 | B41: Hostel facility *
A42: 5 | B42: Transport (school buses) *
A44: BRANDING
A45: 1 | B45: We will send our logo (PNG / SVG) | E45: High resolution, transparent background if possible
...

Sheet 2. Modules
A1: 2 · Modules You Need
A2: Tell us which parts of the ERP you want, how important each is, and anything special about how your school works.
A3: =HYPERLINK("#'Start Here'!A1","← Back to Start Here") -> ← Back to Start Here | C3: Light-blue cells: please fill in · Gold row: example of the format · * required
A5: MODULES
A6: Answer the light-blue columns for every module. Example: Admissions → Yes · High · 15-Mar-2026 · Admission in-charge, Principal · “We admit only in Class 6 and 9, after an entrance test.”
A7: # | B7: Module | C7: What it covers | D7: Do you need it? * | E7: Priority | F7: Needed by (date) | G7: Main users | H7: How it works at your school / special needs
A8: 1 | B8: Admissions | C8: Online parent form, document upload, step-by-step approvals, roll numbers, house allocation, admission letter
A9: 2 | B9: Student records | C9: Student master profile, parents, class & section, status, documents
A10: 3 | B10: Attendance | C10: Daily roll call, monthly register, absent alerts to parents, attendance %
A11: 4 | B11: Timetable & substitution | C11: Auto-generate timetable, teacher workload, cover for absent teachers
A12: 5 | B12: Academics | C12: Subjects, syllabus, lesson plans, assignments
A13: 6 | B13: Exams & report cards | C13: Exam schedule, marks entry, grades, printable report cards
A14: 7 | B14: Online tests (CBT) | C14: Question bank, timed online tests, auto-marking of MCQs
A15: 8 | B15: Fees & payments | C15: Fee structure, invoices, payment recording, receipts, dues
A16: 9 | B16: Leave & gate pass | C16: Staff and student leave, leave balances, hostel gate passes
A17: 10 | B17: Hostel | C17: Hostels, rooms, bed allocation, visitors
A18: 11 | B18: Discipline | C18: Incident records, demerits, confidential notes, parent intimation
A19: 12 | B19: Staff & payroll | C19: Staff directory, salary structure, monthly payslips, leave deductions
... A21: 14 | B21: Reports & dashboards | C21: Summary dashboards, exports to Excel/PDF

Sheet 3. Classes
A1: 3 · Classes & Sections
A2: One row per section. This builds your class list, rosters and the timetable grid.
A3: =HYPERLINK("#'Start Here'!A1","← Back to Start Here") -> ← Back to Start Here | C3: Light-blue cells: please fill in · Gold row: example of the format · * required
A5: CLASSES & SECTIONS
A6: Class * | B6: Section * | C6: Stream | D6: Class teacher | E6: Room | F6: Students (approx) | G6: Notes
A7: Class 10 | B7: A | C7: None | D7: Mrs. Meera Iyer | E7: R-204 | F7: 40 | G7: Gold row is an example — replace or delete

Sheet 4. Subjects
A1: 4 · Subjects
A2: Every subject taught, the classes it is taught in, and how many periods a week it gets.
A3: =HYPERLINK("#'Start Here'!A1","← Back to Start Here") -> ← Back to Start Here | C3: Light-blue cells: please fill in · Gold row: example of the format · * required
A5: SUBJECTS
A6: Subject name * | B6: Short code | C6: Taught in classes * | D6: Type | E6: Periods / week | F6: Max marks | G6: Notes
A7: Mathematics | B7: MAT | C7: Class 6 – 12 | D7: Theory | E7: 6 | F7: 100 | G7: Class 11–12 Science only for Physics

Sheet 5. Staff
A1: 5 · Staff & ERP Roles
A2: Everyone who will use the ERP, and what they should be allowed to do. Each person gets their own login.
A3: =HYPERLINK("#'Start Here'!A1","← Back to Start Here") -> ← Back to Start Here | C3: Light-blue cells: please fill in · Gold row: example of the format · * required
A5: STAFF LIST
A6: ERP role decides what each person can see and change. Pick the closest one; explain exceptions in Notes.
A7: Full name * | B7: Designation * | C7: Department | D7: ERP role * | E7: Email (login) * | F7: Mobile | G7: Subjects taught | H7: Max periods / day | I7: Needs login? *
A8: Mrs. Meera Iyer | B8: PGT Mathematics | C8: Mathematics | D8: Teacher | E8: meera.iyer@school.edu.in | F8: 98450 12345 | G8: Mathematics | H8: 6 | I8: Yes

Sheet 6. Timetable
A1: 6 · Timetable Setup
A2: Your bell schedule and the rules the timetable generator must follow.
A3: =HYPERLINK("#'Start Here'!A1","← Back to Start Here") -> ← Back to Start Here | C3: Light-blue cells: please fill in · Gold row: example of the format · * required
A5: RULES
A6: 1. Periods per day * | F6: Teaching periods only, e.g. 8
A7: 2. Period length (minutes) * | F7: e.g. 45
A8: 3. Max periods per teacher per day * | F8: e.g. 6
A9: 4. Same subject twice in a day? | F9: Allowed for any class?
A10: 5. Who arranges substitutions? | F10: e.g. Vice Principal
A12: BELL SCHEDULE
A13: One row per period, break, lunch or assembly — in order.
A14: Order * | B14: Start time * | C14: End time * | D14: Type * | E14: Name | F14: Notes
A15: 3 | B15: 09:30 | C15: 09:45 | D15: Short break | E15: Break | F15: No classes during breaks

Sheet 7. Fees
A1: 7 · Fee Structure
A2: Every fee you charge, for which classes, how often, and when it is due. Amounts in ₹.
A3: =HYPERLINK("#'Start Here'!A1","← Back to Start Here") -> ← Back to Start Here | C3: Light-blue cells: please fill in · Gold row: example of the format · * required
A5: COLLECTION
A6: 1. Payment modes you accept * | G6: e.g. Cash, UPI, Cheque, NEFT
A7: 2. Online payment gateway | G7: If you already use one, e.g. Razorpay
A8: 3. Terms in a year *
A9: 4. Receipt number format | G9: e.g. RCPT-2026-0001
A10: 5. Sibling / staff-ward concession | G10: Describe the rule, or 'None'
A12: FEE HEADS
A13: One row per fee head per class group.
A14: Classes * | B14: Fee head * | C14: Amount (₹) * | D14: Frequency * | E14: Due date * | F14: Late fee | G14: Notes
A15: Class 6 – 8 | B15: Tuition | C15: 12500 | D15: Per term | E15: 10th of the term's first month | F15: ₹50 per day after 15 days | G15: Refundable: No

Sheet 8. Admissions
A1: 8 · Admissions
A2: How admissions run at your school, and which documents parents must submit.
A3: =HYPERLINK("#'Start Here'!A1","← Back to Start Here") -> ← Back to Start Here | C3: Light-blue cells: please fill in · Gold row: example of the format · * required
A5: PROCESS
A6: 1. Classes you admit into * | F6: e.g. Class 6 and Class 9 only
A7: 2. Admission window * | F7: e.g. January – March
A8: 3. Entrance test? *
A9: 4. Approval steps, in order * | F9: e.g. Office → Accounts → Vice Principal → Principal
A10: 5. Online form for parents? * | F10: Parents fill the form themselves via a link
A11: 6. Roll number format * | F11: e.g. 10A-2026-007 (class-section, year, number)
A12: 7. House system? *
A13: 8. House names | F13: e.g. Red, Blue, Green, Yellow
A14: 9. House allocation
A16: DOCUMENTS PARENTS MUST SUBMIT
A17: Document * | B17: Mandatory? * | C17: Accepted format | D17: Max size | E17: Original needed at school? | F17: Notes
A18: Birth certificate | B18: Yes | C18: PDF or image | D18: 2 MB | E18: Yes | F18: Municipal certificate only

Sheet 9. Hostel
A1: 9 · Hostel
A2: Skip this sheet if you have no hostel. Otherwise: your hostels, rooms and house rules.
A3: =HYPERLINK("#'Start Here'!A1","← Back to Start Here") -> ← Back to Start Here | C3: Light-blue cells: please fill in · Gold row: example of the format · * required
A5: RULES
A6: 1. Visitor days & timings | G6: e.g. Sundays 10:00 – 13:00
A7: 2. Gate pass approval | G7: Who approves a student leaving campus
A8: 3. Parent OTP on student return? | G8: Parent confirms with a one-time code
A10: HOSTELS
A11: Hostel name * | B11: For * | C11: Rooms * | D11: Beds per room * | E11: Warden | F11: Warden mobile | G11: Notes
A12: Shivaji House | B12: Boys | C12: 30 | D12: 4 | E12: Mr. Amit Khanna | F12: 98860 22334 | G12: Class 6–8 only

Sheet 10. Attendance & Leave
A1: 10 · Attendance & Leave
A2: How attendance is taken, and the leave types and yearly quotas for staff and students.
A3: =HYPERLINK("#'Start Here'!A1","← Back to Start Here") -> ← Back to Start Here | C3: Light-blue cells: please fill in · Gold row: example of the format · * required
A5: ATTENDANCE
A6: 1. How is attendance taken? *
A7: 2. Marked by * | G7: e.g. Class teacher, by 09:00
A8: 3. SMS parents when a child is absent? *
A9: 4. Minimum attendance required (%) | G9: e.g. 75
A10: 5. Biometric device brand (if any) | G10: e.g. eSSL, ZKTeco, CAMS
A12: LEAVE TYPES
A13: Leave type * | B13: For * | C13: Days per year * | D13: Paid? * | E13: Carry forward? | F13: Approved by * | G13: Notes
A14: Casual Leave | B14: Staff | C14: 12 | D14: Paid | E14: No | F14: Principal | G14: Max 3 days at a time

Sheet 11. Exams
A1: 11 · Exams
A2: Every exam in the year, the classes that sit it, and how much it counts towards the final result.
A3: =HYPERLINK("#'Start Here'!A1","← Back to Start Here") -> ← Back to Start Here | C3: Light-blue cells: please fill in · Gold row: example of the format · * required
A5: RULES
A6: 1. Result shown as *
A7: 2. Pass mark (%) * | G7: e.g. 33
A8: 3. We will send a sample report card | G8: So the printed report card matches yours
A10: EXAMS IN THE YEAR
A11: Exam name * | B11: Classes * | C11: Month * | D11: Max marks * | E11: Weightage (%) | F11: Type | G11: Notes
A12: Half-Yearly Examination | B12: Class 6 – 12 | C12: September | D12: 80 | E12: 30 | F12: Written | G12: +20 internal assessment

Sheet 12. Grading
A1: 12 · Grading Scale
A2: Your grade bands. Leave blank if you report marks only.
A3: =HYPERLINK("#'Start Here'!A1","← Back to Start Here") -> ← Back to Start Here | C3: Light-blue cells: please fill in · Gold row: example of the format · * required
A5: GRADE BANDS
A6: Highest grade first. Percentages are inclusive.
A7: Grade * | B7: From (%) * | C7: To (%) * | D7: Grade point | E7: Remark on report card
A8: A1 | B8: 91 | C8: 100 | D8: 10 | E8: Outstanding

Sheet 13. Notifications
A1: 13 · Notifications
A2: Which messages go out automatically, to whom, and by which channel.
A3: =HYPERLINK("#'Start Here'!A1","← Back to Start Here") -> ← Back to Start Here | C3: Light-blue cells: please fill in · Gold row: example of the format · * required
A5: CHANNELS
A6: 1 | B6: SMS provider (if any) | F6: e.g. MSG91, Textlocal — or None
A7: 2 | B7: SMS sender ID | F7: 6 letters, e.g. SAINIK
A8: 3 | B8: Email sender address | F8: e.g. noreply@school.edu.in
A9: 4 | B9: WhatsApp Business number | F9: If you have one
A11: AUTOMATIC MESSAGES
A12: Decide each one. Channel can be SMS, Email, WhatsApp or several.
A13: # | B13: Message | C13: Send to | D13: Channel | E13: Needed? * | F13: Notes
A14: 1 | B14: Student absent today
A15: 2 | B15: Fee due reminder
A16: 3 | B16: Fee payment receipt
A17: 4 | B17: Exam results published
A18: 5 | B18: Leave approved / rejected
A19: 6 | B19: Gate pass issued / student returned
A20: 7 | B20: Admission status update
A21: 8 | B21: Holiday / general announcement
A22: 9 | B22: Discipline incident (no confidential details)
A23: 10 | B23: New assignment posted
A24: 11 | B24: Payslip ready (staff)

Sheet 14. Existing Data
A1: 14 · Existing Data
A2: What records you already have, so we can import them instead of typing them in again.
A3: =HYPERLINK("#'Start Here'!A1","← Back to Start Here") -> ← Back to Start Here | C3: Light-blue cells: please fill in · Gold row: example of the format · * required
A5: DATA YOU CAN SEND US
A6: We will share a simple import format for each 'Yes'.
A7: # | B7: Data | C7: Available? * | D7: Kept in | E7: Approx. records | F7: Notes (software name, years covered…)
A8: 1 | B8: Student list (name, class, parents, contacts)
A9: 2 | B9: Parent / guardian contacts
A10: 3 | B10: Staff list
A11: 4 | B11: Fee dues & payments this year
A12: 5 | B12: Past attendance
A13: 6 | B13: Past exam marks
A14: 7 | B14: Current timetable
A15: 8 | B15: Hostel room allotments
A16: 9 | B16: Salary details (for payroll)
A17: 10 | B17: Library books

Sheet 15. Reports
A1: 15 · Reports You Need
A2: Reports, registers and certificates your office produces today — we will match them.
A3: =HYPERLINK("#'Start Here'!A1","← Back to Start Here") -> ← Back to Start Here | C3: Light-blue cells: please fill in · Gold row: example of the format · * required
A5: REPORTS
A6: Report / certificate * | B6: Who uses it | C6: How often | D6: Format | E6: Notes (please attach a sample if possible)
A7: Monthly fee defaulters list | B7: Accountant, Principal | C7: Monthly | D7: Excel | E7: Sorted by class

Sheet 16. Questions & Sign-off
A1: 16 · Questions & Sign-off
A2: Anything we did not ask, any doubts — and who filled in this workbook.
A3: =HYPERLINK("#'Start Here'!A1","← Back to Start Here") -> ← Back to Start Here | C3: Light-blue cells: please fill in · Gold row: example of the format · * required
A5: YOUR QUESTIONS & SPECIAL REQUIREMENTS
A6: # | B6: Question or requirement * | C6: Raised by | D6: Priority | E6: Notes
A7: 1 | B7: Can parents see their child's attendance on their phone? | C7: Principal | D7: Medium
A24: SIGN-OFF
A25: 1 | B25: Filled in by * | E25: Name
A26: 2 | B26: Designation *
A27: 3 | B27: Date * | E27: e.g. 20-Oct-2026
A28: 4 | B28: Approved by (Principal) | E28: Name
